Workbook

Sheet swiss_qna
A2: Staatssekretariat für Wirtschaft SECO
A3: Secrétariat d'Etat à l'économie SECO
A4: Segreteria di Stato dell’economia SECO
A5: Secretariat da stadi per l'economia SECO
A6: State Secretariat for Economic Affairs SECO
A8: You may choose the language to label the Swiss GDP and its production-side components in the dropdown-menu below.
A9: Pages labelled at the end with "_q" contain quarterly data, pages with "_y" contain yearly figures.
A10: Pages labelled at the beginning with "nom" contain figures at current prices, pages with "real" contain values at prices of the preceding year (chained values, reference year 2020), pages with "defl" contain implicit price deflators and those with "gc" contain contributions to real GDP-growth.
A12: Sie können im Dropdown-Menu die Sprache wählen, im welcher Sie das BIP der Schweiz gemäss Produktionsseite beschriftet haben möchten.
A13: Seiten mit der Endbezeichnung "_q" enthalten Quartalszahlen, diejenigen mit "_y" Jahreszahlen.
A14: Seiten mit der Anfangsbezeichnung "nom" enthalten Werte zu laufenden Preisen, diejenigen mit "real" Werte zu Preisen des Vorjahres (verkettet, Referenzjahr 2020), diejenigen mit "defl" implizite Deflatoren und diejenigen mit "gc" Beiträge zum realen BIP-Wachstum.
A16: Vous pouvez choisir ci-dessous la langue avec laquelle vous souhaitez visualiser le PIB de la Suisse selon l'approche par la production.
... A22: Le pagine contrassegnate all'inizio con "nom" contengono dati ai prezzi correnti, pagine con "real" contengono valori ai prezzi dell'anno precedente (serie concatenate, anno di riferimento 2020), pagine con "defl" contengono i deflatori impliciti, pagine con "gc" contengono i contributi alla crescita reale del PIL.

Sheet nom_q
A1: =INDIRECT("beschriftung!"&ADDRESS(beschriftung!$C$1*12+ROW(beschriftung!$A1)-1,COLUMN(beschriftung!A$1))) -> ESA 2010, Quarterly aggregates of Gross Domestic Product, production approach, seasonally, calendar and sport event adjusted data. Background information on sport event adjustment can be found in the publication “Konjunkturtendenzen” (“Economic Trends”) from autumn 2022 and in the technical note from 5 September 2022 on the website www.seco.admin.ch.
A2: =INDIRECT("beschriftung!"&ADDRESS(beschriftung!$C$1*12+ROW(beschriftung!$A2)-1,COLUMN(beschriftung!A$1))) -> In Mio. Swiss Francs, at current prices, percentage change to previous quarter
C4: =INDIRECT("beschriftung!"&ADDRESS(beschriftung!$C$1*12+ROW(beschriftung!$A5)-1,COLUMN(beschriftung!C$1))) -> Gross domestic product | D4: =IF(INDIRECT("beschriftung.!"&ADDRESS(#REF!*12+ROW($A5)-1,COLUMN(D$1)))="","",INDIRECT("beschriftung.!"&ADDRESS(#REF!*12+ROW($A5)-1,COLUMN(D$1)))) -> #REF! | E4: =IF(INDIRECT("beschriftung.!"&ADDRESS(#REF!*12+ROW($A5)-1,COLUMN(E$1)))="","",INDIRECT("beschriftung.!"&ADDRESS(#REF!*12+ROW($A5)-1,COLUMN(E$1)))) -> #REF! | F4: =IF(INDIRECT("beschriftung.!"&ADDRESS(#REF!*12+ROW($A5)-1,COLUMN(F$1)))="","",INDIRECT("beschriftung.!"&ADDRESS(#REF!*12+ROW($A5)-1,COLUMN(F$1)))) -> #REF! | G4: =IF(INDIRECT("beschriftung.!"&ADDRESS(#REF!*12+ROW($A5)-1,COLUMN(G$1)))="","",INDIRECT("beschriftung.!"&ADDRESS(#REF!*12+ROW($A5)-1,COLUMN(G$1)))) -> #REF! | H4: =IF(INDIRECT("beschriftung.!"&ADDRESS(#REF!*12+ROW($A5)-1,COLUMN(H$1)))="","",INDIRECT("beschriftung.!"&ADDRESS(#REF!*12+ROW($A5)-1,COLUMN(H$1)))) -> #REF! | I4: =IF(INDIRECT("beschriftung.!"&ADDRESS(#REF!*12+ROW($A5)-1,COLUMN(I$1)))="","",INDIRECT("beschriftung.!"&ADDRESS(#REF!*12+ROW($A5)-1,COLUMN(I$1)))) -> #REF! | J4: =IF(INDIRECT("beschriftung.!"&ADDRESS(#REF!*12+ROW($A5)-1,COLUMN(J$1)))="","",INDIRECT("beschriftung.!"&ADDRESS(#REF!*12+ROW($A5)-1,COLUMN(J$1)))) -> #REF! | K4: =IF(INDIRECT("beschriftung.!"&ADDRESS(#REF!*12+ROW($A5)-1,COLUMN(K$1)))="","",INDIRECT("beschriftung.!"&ADDRESS(#REF!*12+ROW($A5)-1,COLUMN(K$1)))) -> #REF! | L4: =IF(INDIRECT("beschriftung.!"&ADDRESS(#REF!*12+ROW($A5)-1,COLUMN(L$1)))="","",INDIRECT("beschriftung.!"&ADDRESS(#REF!*12+ROW($A5)-1,COLUMN(L$1)))) -> #REF! | Q4: =IF(INDIRECT("beschriftung.!"&ADDRESS(#REF!*12+ROW($A5)-1,COLUMN(Q$1)))="","",INDIRECT("beschriftung.!"&ADDRESS(#REF!*12+ROW($A5)-1,COLUMN(Q$1)))) -> #REF! | R4: =IF(INDIRECT("beschriftung.!"&ADDRESS(#REF!*12+ROW($A5)-1,COLUMN(R$1)))="","",INDIRECT("beschriftung.!"&ADDRESS(#REF!*12+ROW($A5)-1,COLUMN(R$1)))) -> #REF! | U4: =IF(INDIRECT("beschriftung.!"&ADDRESS(#REF!*12+ROW($A5)-1,COLUMN(U$1)))="","",INDIRECT("beschriftung.!"&ADDRESS(#REF!*12+ROW($A5)-1,COLUMN(U$1)))) -> #REF! | V4: =IF(INDIRECT("beschriftung.!"&ADDRESS(#REF!*12+ROW($A5)-1,COLUMN(V$1)))="","",INDIRECT("beschriftung.!"&ADDRESS(#REF!*12+ROW($A5)-1,COLUMN(V$1)))) -> #REF! | W4: =IF(INDIRECT("beschriftung.!"&ADDRESS(#REF!*12+ROW($A5)-1,COLUMN(W$1)))="","",INDIRECT("beschriftung.!"&ADDRESS(#REF!*12+ROW($A5)-1,COLUMN(W$1)))) -> #REF! | X4: =IF(INDIRECT("beschriftung.!"&ADDRESS(#REF!*12+ROW($A5)-1,COLUMN(X$1)))="","",INDIRECT("beschriftung.!"&ADDRESS(#REF!*12+ROW($A5)-1,COLUMN(X$1)))) -> #REF! | AA4: =IF(INDIRECT("beschriftung.!"&ADDRESS(#REF!*12+ROW($A5)-1,COLUMN(AA$1)))="","",INDIRECT("beschriftung.!"&ADDRESS(#REF!*12+ROW($A5)-1,COLUMN(AA$1)))) -> #REF! | AB4: =IF(INDIRECT("beschriftung.!"&ADDRESS(#REF!*12+ROW($A5)-1,COLUMN(AB$1)))="","",INDIRECT("beschriftung.!"&ADDRESS(#REF!*12+ROW($A5)-1,COLUMN(AB$1)))) -> #REF! | AG4: =IF(INDIRECT("beschriftung.!"&ADDRESS(#REF!*12+ROW($A5)-1,COLUMN(AG$1)))="","",INDIRECT("beschriftung.!"&ADDRESS(#REF!*12+ROW($A5)-1,COLUMN(AG$1)))) -> #REF! | AH4: =IF(INDIRECT("beschriftung.!"&ADDRESS(#REF!*12+ROW($A5)-1,COLUMN(AH$1)))="","",INDIRECT("beschriftung.!"&ADDRESS(#REF!*12+ROW($A5)-1,COLUMN(AH$1)))) -> #REF! | AI4: =IF(INDIRECT("beschriftung.!"&ADDRESS(#REF!*12+ROW($A5)-1,COLUMN(AI$1)))="","",INDIRECT("beschriftung.!"&ADDRESS(#REF!*12+ROW($A5)-1,COLUMN(AI$1)))) -> #REF! | AJ4: =IF(INDIRECT("beschriftung.!"&ADDRESS(#REF!*12+ROW($A5)-1,COLUMN(AJ$1)))="","",INDIRECT("beschriftung.!"&ADDRESS(#REF!*12+ROW($A5)-1,COLUMN(AJ$1)))) -> #REF! | AM4: =IF(INDIRECT("beschriftung.!"&ADDRESS(#REF!*12+ROW($A5)-1,COLUMN(AM$1)))="","",INDIRECT("beschriftung.!"&ADDRESS(#REF!*12+ROW($A5)-1,COLUMN(AM$1)))) -> #REF! | AN4: =IF(INDIRECT("beschriftung.!"&ADDRESS(#REF!*12+ROW($A5)-1,COLUMN(AN$1)))="","",INDIRECT("beschriftung.!"&ADDRESS(#REF!*12+ROW($A5)-1,COLUMN(AN$1)))) -> #REF! | AO4: =IF(INDIRECT("beschriftung.!"&ADDRESS(#REF!*12+ROW($A5)-1,COLUMN(AO$1)))="","",INDIRECT("beschriftung.!"&ADDRESS(#REF!*12+ROW($A5)-1,COLUMN(AO$1)))) -> #REF! | AP4: =IF(INDIRECT("beschriftung.!"&ADDRESS(#REF!*12+ROW($A5)-1,COLUMN(AP$1)))="","",INDIRECT("beschriftung.!"&ADDRESS(#REF!*12+ROW($A5)-1,COLUMN(AP$1)))) -> #REF! | AQ4: =IF(INDIRECT("beschriftung.!"&ADDRESS(#REF!*12+ROW($A5)-1,COLUMN(AQ$1)))="","",INDIRECT("beschriftung.!"&ADDRESS(#REF!*12+ROW($A5)-1,COLUMN(AQ$1)))) -> #REF! | AR4: =IF(INDIRECT("beschriftung.!"&ADDRESS(#REF!*12+ROW($A5)-1,COLUMN(AR$1)))="","",INDIRECT("beschriftung.!"&ADDRESS(#REF!*12+ROW($A5)-1,COLUMN(AR$1)))) -> #REF! | AS4: =IF(INDIRECT("beschriftung.!"&ADDRESS(#REF!*12+ROW($A5)-1,COLUMN(AS$1)))="","",INDIRECT("beschriftung.!"&ADDRESS(#REF!*12+ROW($A5)-1,COLUMN(AS$1)))) -> #REF! | AT4: =IF(INDIRECT("beschriftung.!"&ADDRESS(#REF!*12+ROW($A5)-1,COLUMN(AT$1)))="","",INDIRECT("beschriftung.!"&ADDRESS(#REF!*12+ROW($A5)-1,COLUMN(AT$1)))) -> #REF! | ... AV4: =IF(INDIRECT("beschriftung.!"&ADDRESS(#REF!*12+ROW($A5)-1,COLUMN(AV$1)))="","",INDIRECT("beschriftung.!"&ADDRESS(#REF!*12+ROW($A5)-1,COLUMN(AV$1)))) -> #REF! | AY4: =IF(INDIRECT("beschriftung.!"&ADDRESS(#REF!*12+ROW($A5)-1,COLUMN(AY$1)))="","",INDIRECT("beschriftung.!"&ADDRESS(#REF!*12+ROW($A5)-1,COLUMN(AY$1)))) -> #REF! | AZ4: =IF(INDIRECT("beschriftung.!"&ADDRESS(#REF!*12+ROW($A5)-1,COLUMN(AZ$1)))="","",INDIRECT("beschriftung.!"&ADDRESS(#REF!*12+ROW($A5)-1,COLUMN(AZ$1)))) -> #REF! | BA4: =IF(INDIRECT("beschriftung.!"&ADDRESS(#REF!*12+ROW($A5)-1,COLUMN(BA$1)))="","",INDIRECT("beschriftung.!"&ADDRESS(#REF!*12+ROW($A5)-1,COLUMN(BA$1)))) -> #REF! | BB4: =IF(INDIRECT("beschriftung.!"&ADDRESS(#REF!*12+ROW($A5)-1,COLUMN(BB$1)))="","",INDIRECT("beschriftung.!"&ADDRESS(#REF!*12+ROW($A5)-1,COLUMN(BB$1)))) -> #REF! | BC4: =IF(INDIRECT("beschriftung.!"&ADDRESS(#REF!*12+ROW($A5)-1,COLUMN(BC$1)))="","",INDIRECT("beschriftung.!"&ADDRESS(#REF!*12+ROW($A5)-1,COLUMN(BC$1)))) -> #REF! | BD4: =IF(INDIRECT("beschriftung.!"&ADDRESS(#REF!*12+ROW($A5)-1,COLUMN(BD$1)))="","",INDIRECT("beschriftung.!"&ADDRESS(#REF!*12+ROW($A5)-1,COLUMN(BD$1)))) -> #REF! | BE4: =IF(INDIRECT("beschriftung.!"&ADDRESS(#REF!*12+ROW($A5)-1,COLUMN(BE$1)))="","",INDIRECT("beschriftung.!"&ADDRESS(#REF!*12+ROW($A5)-1,COLUMN(BE$1)))) -> #REF! | BF4: =IF(INDIRECT("beschriftung.!"&ADDRESS(#REF!*12+ROW($A5)-1,COLUMN(BF$1)))="","",INDIRECT("beschriftung.!"&ADDRESS(#REF!*12+ROW($A5)-1,COLUMN(BF$1)))) -> #REF!
E5: =INDIRECT("beschriftung!"&ADDRESS(beschriftung!$C$1*12+ROW(beschriftung!$A6)-1,COLUMN(beschriftung!D$1))) -> Gross value added before adjustments | F5: =IF(INDIRECT("beschriftung.!"&ADDRESS(#REF!*12+ROW($A6)-1,COLUMN(F$1)))="","",INDIRECT("beschriftung.!"&ADDRESS(#REF!*12+ROW($A6)-1,COLUMN(F$1)))) -> #REF! | G5: =IF(INDIRECT("beschriftung.!"&ADDRESS(#REF!*12+ROW($A6)-1,COLUMN(G$1)))="","",INDIRECT("beschriftung.!"&ADDRESS(#REF!*12+ROW($A6)-1,COLUMN(G$1)))) -> #REF! | H5: =IF(INDIRECT("beschriftung.!"&ADDRESS(#REF!*12+ROW($A6)-1,COLUMN(H$1)))="","",INDIRECT("beschriftung.!"&ADDRESS(#REF!*12+ROW($A6)-1,COLUMN(H$1)))) -> #REF! | I5: =IF(INDIRECT("beschriftung.!"&ADDRESS(#REF!*12+ROW($A6)-1,COLUMN(I$1)))="","",INDIRECT("beschriftung.!"&ADDRESS(#REF!*12+ROW($A6)-1,COLUMN(I$1)))) -> #REF! | J5: =IF(INDIRECT("beschriftung.!"&ADDRESS(#REF!*12+ROW($A6)-1,COLUMN(J$1)))="","",INDIRECT("beschriftung.!"&ADDRESS(#REF!*12+ROW($A6)-1,COLUMN(J$1)))) -> #REF! | K5: =IF(INDIRECT("beschriftung.!"&ADDRESS(#REF!*12+ROW($A6)-1,COLUMN(K$1)))="","",INDIRECT("beschriftung.!"&ADDRESS(#REF!*12+ROW($A6)-1,COLUMN(K$1)))) -> #REF! | L5: =IF(INDIRECT("beschriftung.!"&ADDRESS(#REF!*12+ROW($A6)-1,COLUMN(L$1)))="","",INDIRECT("beschriftung.!"&ADDRESS(#REF!*12+ROW($A6)-1,COLUMN(L$1)))) -> #REF! | Q5: =IF(INDIRECT("beschriftung.!"&ADDRESS(#REF!*12+ROW($A6)-1,COLUMN(Q$1)))="","",INDIRECT("beschriftung.!"&ADDRESS(#REF!*12+ROW($A6)-1,COLUMN(Q$1)))) -> #REF! | R5: =IF(INDIRECT("beschriftung.!"&ADDRESS(#REF!*12+ROW($A6)-1,COLUMN(R$1)))="","",INDIRECT("beschriftung.!"&ADDRESS(#REF!*12+ROW($A6)-1,COLUMN(R$1)))) -> #REF! | U5: =IF(INDIRECT("beschriftung.!"&ADDRESS(#REF!*12+ROW($A6)-1,COLUMN(U$1)))="","",INDIRECT("beschriftung.!"&ADDRESS(#REF!*12+ROW($A6)-1,COLUMN(U$1)))) -> #REF! | V5: =IF(INDIRECT("beschriftung.!"&ADDRESS(#REF!*12+ROW($A6)-1,COLUMN(V$1)))="","",INDIRECT("beschriftung.!"&ADDRESS(#REF!*12+ROW($A6)-1,COLUMN(V$1)))) -> #REF! | W5: =IF(INDIRECT("beschriftung.!"&ADDRESS(#REF!*12+ROW($A6)-1,COLUMN(W$1)))="","",INDIRECT("beschriftung.!"&ADDRESS(#REF!*12+ROW($A6)-1,COLUMN(W$1)))) -> #REF! | X5: =IF(INDIRECT("beschriftung.!"&ADDRESS(#REF!*12+ROW($A6)-1,COLUMN(X$1)))="","",INDIRECT("beschriftung.!"&ADDRESS(#REF!*12+ROW($A6)-1,COLUMN(X$1)))) -> #REF! | AA5: =IF(INDIRECT("beschriftung.!"&ADDRESS(#REF!*12+ROW($A6)-1,COLUMN(AA$1)))="","",INDIRECT("beschriftung.!"&ADDRESS(#REF!*12+ROW($A6)-1,COLUMN(AA$1)))) -> #REF! | AB5: =IF(INDIRECT("beschriftung.!"&ADDRESS(#REF!*12+ROW($A6)-1,COLUMN(AB$1)))="","",INDIRECT("beschriftung.!"&ADDRESS(#REF!*12+ROW($A6)-1,COLUMN(AB$1)))) -> #REF! | AG5: =IF(INDIRECT("beschriftung.!"&ADDRESS(#REF!*12+ROW($A6)-1,COLUMN(AG$1)))="","",INDIRECT("beschriftung.!"&ADDRESS(#REF!*12+ROW($A6)-1,COLUMN(AG$1)))) -> #REF! | AH5: =IF(INDIRECT("beschriftung.!"&ADDRESS(#REF!*12+ROW($A6)-1,COLUMN(AH$1)))="","",INDIRECT("beschriftung.!"&ADDRESS(#REF!*12+ROW($A6)-1,COLUMN(AH$1)))) -> #REF! | AI5: =IF(INDIRECT("beschriftung.!"&ADDRESS(#REF!*12+ROW($A6)-1,COLUMN(AI$1)))="","",INDIRECT("beschriftung.!"&ADDRESS(#REF!*12+ROW($A6)-1,COLUMN(AI$1)))) -> #REF! | AJ5: =IF(INDIRECT("beschriftung.!"&ADDRESS(#REF!*12+ROW($A6)-1,COLUMN(AJ$1)))="","",INDIRECT("beschriftung.!"&ADDRESS(#REF!*12+ROW($A6)-1,COLUMN(AJ$1)))) -> #REF! | AM5: =IF(INDIRECT("beschriftung.!"&ADDRESS(#REF!*12+ROW($A6)-1,COLUMN(AM$1)))="","",INDIRECT("beschriftung.!"&ADDRESS(#REF!*12+ROW($A6)-1,COLUMN(AM$1)))) -> #REF! | AN5: =IF(INDIRECT("beschriftung.!"&ADDRESS(#REF!*12+ROW($A6)-1,COLUMN(AN$1)))="","",INDIRECT("beschriftung.!"&ADDRESS(#REF!*12+ROW($A6)-1,COLUMN(AN$1)))) -> #REF! | AO5: =IF(INDIRECT("beschriftung.!"&ADDRESS(#REF!*12+ROW($A6)-1,COLUMN(AO$1)))="","",INDIRECT("beschriftung.!"&ADDRESS(#REF!*12+ROW($A6)-1,COLUMN(AO$1)))) -> #REF! | AP5: =IF(INDIRECT("beschriftung.!"&ADDRESS(#REF!*12+ROW($A6)-1,COLUMN(AP$1)))="","",INDIRECT("beschriftung.!"&ADDRESS(#REF!*12+ROW($A6)-1,COLUMN(AP$1)))) -> #REF! | AQ5: =IF(INDIRECT("beschriftung.!"&ADDRESS(#REF!*12+ROW($A6)-1,COLUMN(AQ$1)))="","",INDIRECT("beschriftung.!"&ADDRESS(#REF!*12+ROW($A6)-1,COLUMN(AQ$1)))) -> #REF! | AR5: =IF(INDIRECT("beschriftung.!"&ADDRESS(#REF!*12+ROW($A6)-1,COLUMN(AR$1)))="","",INDIRECT("beschriftung.!"&ADDRESS(#REF!*12+ROW($A6)-1,COLUMN(AR$1)))) -> #REF! | AS5: =IF(INDIRECT("beschriftung.!"&ADDRESS(#REF!*12+ROW($A6)-1,COLUMN(AS$1)))="","",INDIRECT("beschriftung.!"&ADDRESS(#REF!*12+ROW($A6)-1,COLUMN(AS$1)))) -> #REF! | AT5: =IF(INDIRECT("beschriftung.!"&ADDRESS(#REF!*12+ROW($A6)-1,COLUMN(AT$1)))="","",INDIRECT("beschriftung.!"&ADDRESS(#REF!*12+ROW($A6)-1,COLUMN(AT$1)))) -> #REF! | ... AV5: =IF(INDIRECT("beschriftung.!"&ADDRESS(#REF!*12+ROW($A6)-1,COLUMN(AV$1)))="","",INDIRECT("beschriftung.!"&ADDRESS(#REF!*12+ROW($A6)-1,COLUMN(AV$1)))) -> #REF! | AY5: =IF(INDIRECT("beschriftung.!"&ADDRESS(#REF!*12+ROW($A6)-1,COLUMN(AY$1)))="","",INDIRECT("beschriftung.!"&ADDRESS(#REF!*12+ROW($A6)-1,COLUMN(AY$1)))) -> #REF! | AZ5: =IF(INDIRECT("beschriftung.!"&ADDRESS(#REF!*12+ROW($A6)-1,COLUMN(AZ$1)))="","",INDIRECT("beschriftung.!"&ADDRESS(#REF!*12+ROW($A6)-1,COLUMN(AZ$1)))) -> #REF! | BA5: =INDIRECT("beschriftung!"&ADDRESS(beschriftung!$C$1*12+ROW(beschriftung!$A6)-1,COLUMN(beschriftung!AS$1))) -> Adjustments | BB5: =IF(INDIRECT("beschriftung.!"&ADDRESS(#REF!*12+ROW($A6)-1,COLUMN(BB$1)))="","",INDIRECT("beschriftung.!"&ADDRESS(#REF!*12+ROW($A6)-1,COLUMN(BB$1)))) -> #REF! | BC5: =IF(INDIRECT("beschriftung.!"&ADDRESS(#REF!*12+ROW($A6)-1,COLUMN(BC$1)))="","",INDIRECT("beschriftung.!"&ADDRESS(#REF!*12+ROW($A6)-1,COLUMN(BC$1)))) -> #REF! | BD5: =IF(INDIRECT("beschriftung.!"&ADDRESS(#REF!*12+ROW($A6)-1,COLUMN(BD$1)))="","",INDIRECT("beschriftung.!"&ADDRESS(#REF!*12+ROW($A6)-1,COLUMN(BD$1)))) -> #REF! | BE5: =IF(INDIRECT("beschriftung.!"&ADDRESS(#REF!*12+ROW($A6)-1,COLUMN(BE$1)))="","",INDIRECT("beschriftung.!"&ADDRESS(#REF!*12+ROW($A6)-1,COLUMN(BE$1)))) -> #REF! | BF5: =IF(INDIRECT("beschriftung.!"&ADDRESS(#REF!*12+ROW($A6)-1,COLUMN(BF$1)))="","",INDIRECT("beschriftung.!"&ADDRESS(#REF!*12+ROW($A6)-1,COLUMN(BF$1)))) -> #REF!
G6: =INDIRECT("beschriftung!"&ADDRESS(beschriftung!$C$1*12+ROW(beschriftung!$A7)-1,COLUMN(beschriftung!E$1))) -> Agriculture, forestry and fishing | I6: =INDIRECT("beschriftung!"&ADDRESS(beschriftung!$C$1*12+ROW(beschriftung!$A7)-1,COLUMN(beschriftung!G$1))) -> Mining and quarrying | K6: =INDIRECT("beschriftung!"&ADDRESS(beschriftung!$C$1*12+ROW(beschriftung!$A7)-1,COLUMN(beschriftung!I$1))) -> Manufacturing | Q6: =INDIRECT("beschriftung!"&ADDRESS(beschriftung!$C$1*12+ROW(beschriftung!$A7)-1,COLUMN(beschriftung!M$1))) -> Electricity, gas, steam and air conditioning supply | S6: =INDIRECT("beschriftung!"&ADDRESS(beschriftung!$C$1*12+ROW(beschriftung!$A7)-1,COLUMN(beschriftung!O$1))) -> Water supply, sewerage, waste management and remediation activities | U6: =INDIRECT("beschriftung!"&ADDRESS(beschriftung!$C$1*12+ROW(beschriftung!$A7)-1,COLUMN(beschriftung!Q$1))) -> Construction | W6: =INDIRECT("beschriftung!"&ADDRESS(beschriftung!$C$1*12+ROW(beschriftung!$A7)-1,COLUMN(beschriftung!S$1))) -> Trade, repair of motor vehicles and motorcycles | AA6: =INDIRECT("beschriftung!"&ADDRESS(beschriftung!$C$1*12+ROW(beschriftung!$A7)-1,COLUMN(beschriftung!W$1))) -> Transportation and storage | AC6: =INDIRECT("beschriftung!"&ADDRESS(beschriftung!$C$1*12+ROW(beschriftung!$A7)-1,COLUMN(beschriftung!Y$1))) -> Accommodation and food service activities | AE6: =INDIRECT("beschriftung!"&ADDRESS(beschriftung!$C$1*12+ROW(beschriftung!$A7)-1,COLUMN(beschriftung!X$1))) -> Information and communication | AG6: =INDIRECT("beschriftung!"&ADDRESS(beschriftung!$C$1*12+ROW(beschriftung!$A7)-1,COLUMN(beschriftung!AA$1))) -> Financial and insurance activities | AM6: =INDIRECT("beschriftung!"&ADDRESS(beschriftung!$C$1*12+ROW(beschriftung!$A7)-1,COLUMN(beschriftung!AE$1))) -> Real estate, professional, scientific, technical activities and administrative services | AO6: =INDIRECT("beschriftung!"&ADDRESS(beschriftung!$C$1*12+ROW(beschriftung!$A7)-1,COLUMN(beschriftung!AG$1))) -> Public administration | AQ6: =INDIRECT("beschriftung!"&ADDRESS(beschriftung!$C$1*12+ROW(beschriftung!$A7)-1,COLUMN(beschriftung!AI$1))) -> Education | AS6: =INDIRECT("beschriftung!"&ADDRESS(beschriftung!$C$1*12+ROW(beschriftung!$A7)-1,COLUMN(beschriftung!AK$1))) -> Human health and social work activities | AU6: =INDIRECT("beschriftung!"&ADDRESS(beschriftung!$C$1*12+ROW(beschriftung!$A7)-1,COLUMN(beschriftung!AM$1))) -> Arts, entertainment and recreation | AW6: =INDIRECT("beschriftung!"&ADDRESS(beschriftung!$C$1*12+ROW(beschriftung!$A7)-1,COLUMN(beschriftung!AO$1))) -> Other service activities | AY6: =INDIRECT("beschriftung!"&ADDRESS(beschriftung!$C$1*12+ROW(beschriftung!$A7)-1,COLUMN(beschriftung!AQ$1))) -> Activities of housholds as employers and producers for own use | BC6: =INDIRECT("beschriftung!"&ADDRESS(beschriftung!$C$1*12+ROW(beschriftung!$A7)-1,COLUMN(beschriftung!AU$1))) -> Taxes on products | BE6: =INDIRECT("beschriftung!"&ADDRESS(beschriftung!$C$1*12+ROW(beschriftung!$A7)-1,COLUMN(beschriftung!AW$1))) -> Subsidies on products
M8: =INDIRECT("beschriftung!"&ADDRESS(beschriftung!$C$1*12+ROW(beschriftung!$A7),COLUMN(beschriftung!J$1))) -> thereof chemicals and pharmaceuticals | O8: =INDIRECT("beschriftung!"&ADDRESS(beschriftung!$C$1*12+ROW(beschriftung!$A7),COLUMN(beschriftung!K$1))) -> thereof other manufacturing | Y8: =INDIRECT("beschriftung!"&ADDRESS(beschriftung!$C$1*12+ROW(beschriftung!$A7),COLUMN(beschriftung!U$1))) -> thereof retail trade | AI8: =INDIRECT("beschriftung!"&ADDRESS(beschriftung!$C$1*12+ROW(beschriftung!$A7),COLUMN(beschriftung!AB$1))) -> thereof financial activities | AK8: =INDIRECT("beschriftung!"&ADDRESS(beschriftung!$C$1*12+ROW(beschriftung!$A7),COLUMN(beschriftung!AC$1))) -> thereof insurance activities
C11: B1GQ | E11: B1G | G11: NOGA 01-03 | I11: NOGA 05-09 | K11: NOGA 10-33 | M11: NOGA 19-21 | O11: NOGA 10-18; 22-33 | Q11: NOGA 35 | S11: NOGA 36-39 | U11: NOGA 41-43 | W11: NOGA 45-47 | Y11: NOGA 47 | AA11: NOGA 49-53 | AC11: NOGA 55-56 | AE11: NOGA 58-63 | AG11: NOGA 64-66 | AI11: NOGA 64 | AK11: NOGA 65 | AM11: NOGA 68-75; 77-82 | AO11: NOGA 84 | AQ11: NOGA 85 | AS11: NOGA 86-88 | AU11: NOGA 90-93 | AW11: NOGA 94-96 | AY11: NOGA 97-98 | BC11: D21 | BE11: D31
A12: 1980 | B12: 1 | C12: 50870.618
A13: 1980 | B13: 2 | C13: 51589.145 | D13: 0.014124589
A14: 1980 | B14: 3 | C14: 52513.466 | D14: 0.017916971
A15: 1980 | B15: 4 | C15: 53339.752 | D15: 0.015734749
A16: 1981 | B16: 1 | C16: 54375.816 | D16: 0.019423863
A17: 1981 | B17: 2 | C17: 55376.645 | D17: 0.018405779
A18: 1981 | B18: 3 | C18: 56529.103 | D18: 0.020811258
A19: 1981 | B19: 4 | C19: 57563.974 | D19: 0.018306875
A20: 1982 | B20: 1 | C20: 58319.838 | D20: 0.013130849
A21: 1982 | B21: 2 | C21: 59218.778 | D21: 0.015413966
A22: 1982 | B22: 3 | C22: 59558.125 | D22: 0.0057303913
A23: 1982 | B23: 4 | C23: 59956.44 | D23: 0.006687847
A24: 1983 | B24: 1 | C24: 60303.401 | D24: 0.0057868779
... A51: 1989 | B51: 4 | C51: 88956.945 | D51: 0.019393573
A52: 1990 | B52: 1 | C52: 91808.989 | D52: 0.032060943 | E52: 89445.856 | G52: 1960.2375 | I52: 133.81587 | K52: 18186.395 | M52: 2906.6144 | O52: 15279.781 | Q52: 1495.4401 | S52: 719.76595 | U52: 7022.6814 | W52: 15313.873 | Y52: 5173.9942 | AA52: 3712.516 | AC52: 1905.1715 | AE52: 4076.9261 | AG52: 6916.1967 | AI52: 2914.402 | AK52: 3787.8453 | AM52: 12569.222 | AO52: 5664.9838 | AQ52: 3830.8505 | AS52: 3854.4179 | AU52: 299.64157 | AW52: 1491.7816 | AY52: 291.93879 | BA52: 2363.1326 | BC52: 4365.015 | BE52: -2001.8824
A53: 1990 | B53: 2 | C53: 93393.795 | D53: 0.017261995 | E53: 90884.458 | F53: 0.016083491 | G53: 1950.9987 | H53: -0.0047131279 | I53: 135.21476 | J53: 0.01045387 | K53: 18482.001 | L53: 0.016254235 | M53: 2932.5079 | N53: 0.0089084906 | O53: 15549.493 | P53: 0.017651588 | Q53: 1597.6288 | R53: 0.068333481 | S53: 732.8525 | T53: 0.018181675 | U53: 7164.1359 | V53: 0.020142519 | W53: 15497.007 | X53: 0.011958682 | Y53: 5271.4462 | Z53: 0.018834962 | AA53: 3678.8953 | AB53: -0.009056053 | AC53: 2008.5387 | AD53: 0.054256102 | AE53: 4109.7071 | AF53: 0.0080406136 | AG53: 6834.3763 | AH53: -0.011830255 | AI53: 2748.2703 | AJ53: -0.057003702 | AK53: 3879.2698 | AL53: 0.024136293 | AM53: 12813.31 | AN53: 0.019419454 | AO53: 5853.8668 | AP53: 0.033342184 | AQ53: 3985.1021 | AR53: 0.040265624 | AS53: 3914.2832 | AT53: 0.015531608 | AU53: 297.70051 | AV53: -0.0064779232 | AW53: 1526.4271 | AX53: 0.023224222 | AY53: 302.41233 | AZ53: 0.03587581 | BA53: 2509.3373 | BB53: 0.061869015 | BC53: 4481.1211 | BD53: 0.02659924 | BE53: -1971.7838 | BF53: -0.015035152
A54: 1990 | B54: 3 | C54: 94439.244 | D54: 0.011193987 | E54: 91890.878 | F54: 0.011073622 | G54: 1940.9827 | H54: -0.005133735 | I54: 136.77985 | J54: 0.011574872 | K54: 18524.023 | L54: 0.0022736709 | M54: 2955.1093 | N54: 0.0077071875 | O54: 15568.914 | P54: 0.0012489539 | Q54: 1511.3585 | R54: -0.053998958 | S54: 741.93887 | T54: 0.01239863 | U54: 7299.5857 | V54: 0.018906654 | W54: 15459.708 | X54: -0.0024068607 | Y54: 5304.9701 | Z54: 0.0063595412 | AA54: 3703.1908 | AB54: 0.0066040184 | AC54: 2068.6912 | AD54: 0.029948386 | AE54: 4178.9786 | AF54: 0.016855563 | AG54: 6953.1812 | AH54: 0.017383423 | AI54: 2810.8424 | AJ54: 0.022767821 | AK54: 3937.7474 | AL54: 0.015074367 | AM54: 13080.292 | AN54: 0.020836363 | AO54: 6008.9934 | AP54: 0.026499849 | AQ54: 4112.9927 | AR54: 0.032092183 | AS54: 3992.1304 | AT54: 0.019887983 | AU54: 317.67221 | AV54: 0.067086548 | AW54: 1549.4111 | AX54: 0.015057441 | AY54: 310.96731 | AZ54: 0.028289103 | BA54: 2548.3661 | BB54: 0.01555343 | BC54: 4550.5 | BD54: 0.015482493 | BE54: -2002.1339 | BF54: 0.015392216
A55: 1990 | B55: 4 | C55: 95256.881 | D55: 0.0086578082 | E55: 92782.255 | F55: 0.0097003807 | G55: 1925.7276 | H55: -0.0078594991 | I55: 140.55054 | J55: 0.027567598 | K55: 18691.693 | L55: 0.009051451 | M55: 3020.539 | N55: 0.022141201 | O55: 15671.154 | P55: 0.0065669077 | Q55: 1702.0942 | R55: 0.12620151 | S55: 744.21761 | T55: 0.0030713341 | U55: 7369.2126 | V55: 0.0095384641 | W55: 15047.521 | X55: -0.026661992 | Y55: 5263.9002 | Z55: -0.0077417912 | AA55: 3879.9949 | AB55: 0.047743729 | AC55: 2120.0049 | AD55: 0.024804886 | AE55: 4233.1918 | AF55: 0.012972847 | AG55: 6980.7672 | AH55: 0.0039673982 | AI55: 2814.8056 | AJ55: 0.0014099812 | AK55: 3962.7774 | AL55: 0.0063564334 | AM55: 13391.527 | AN55: 0.02379416 | AO55: 6165.2876 | AP55: 0.026010051 | AQ55: 4158.3711 | AR55: 0.011032935 | AS55: 4027.4387 | AT55: 0.0088444761 | AU55: 335.39524 | AV55: 0.055790301 | AW55: 1551.4692 | AX55: 0.0013282717 | AY55: 317.79065 | AZ55: 0.02194233 | BA55: 2474.6264 | BB55: -0.028936048 | BC55: 4522.3249 | BD55: -0.0061916399 | BE55: -2047.6985 | BF55: 0.022758011
A56: 1991 | B56: 1 | C56: 96921.677 | D56: 0.017476911 | E56: 94585.364 | F56: 0.019433777 | G56: 1913.2567 | H56: -0.006475959 | I56: 145.49725 | J56: 0.035195206 | K56: 19027.874 | L56: 0.017985581 | M56: 3084.9596 | N56: 0.021327544 | O56: 15942.914 | P56: 0.017341434 | Q56: 1814.2325 | R56: 0.065882553 | S56: 731.92813 | T56: -0.016513285 | U56: 7370.8441 | V56: 0.00022140091 | W56: 15103.064 | X56: 0.0036911477 | Y56: 5204.512 | Z56: -0.011282157 | AA56: 4174.7032 | AB56: 0.075955847 | AC56: 2163.5884 | AD56: 0.02055822 | AE56: 4406.9816 | AF56: 0.041054074 | AG56: 7255.1677 | AH56: 0.039308074 | AI56: 3081.9617 | AJ56: 0.094911 | AK56: 3953.2416 | AL56: -0.0024063324 | AM56: 13704.239 | AN56: 0.023351503 | AO56: 6281.6841 | AP56: 0.018879337 | AQ56: 4160.8311 | AR56: 0.00059158649 | AS56: 4100.0047 | AT56: 0.018017888 | AU56: 367.51887 | AV56: 0.09577844 | AW56: 1541.2205 | AX56: -0.0066057633 | AY56: 322.72863 | AZ56: 0.015538461 | BA56: 2336.3129 | BB56: -0.055892694 | BC56: 4515.2932 | BD56: -0.0015548951 | BE56: -2178.9803 | BF56: 0.064111878
A57: 1991 | B57: 2 | C57: 97276.914 | D57: 0.0036651918 | E57: 95053.52 | F57: 0.0049495619 | G57: 1956.3475 | H57: 0.022522251 | I57: 148.5414 | J57: 0.02092236 | K57: 19160.399 | L57: 0.0069648139 | M57: 3111.6405 | N57: 0.0086486749 | O57: 16048.759 | P57: 0.0066389862 | Q57: 1762.9788 | R57: -0.028250898 | S57: 723.39972 | T57: -0.011651978 | U57: 7342.7652 | V57: -0.0038094558 | W57: 14514.239 | X57: -0.038987081 | Y57: 5115.597 | Z57: -0.017084209 | AA57: 4440.1346 | AB57: 0.063580887 | AC57: 2189.5206 | AD57: 0.011985741 | AE57: 4517.7465 | AF57: 0.025133958 | AG57: 7394.6292 | AH57: 0.019222363 | AI57: 3203.4481 | AJ57: 0.039418555 | AK57: 3953.1093 | AL57: -3.3470915e-05 | AM57: 13895.627 | AN57: 0.013965624 | AO57: 6397.4218 | AP57: 0.018424625 | AQ57: 4164.941 | AR57: 0.00098775551 | AS57: 4212.7191 | AT57: 0.027491288 | AU57: 380.21971 | AV57: 0.034558336 | AW57: 1523.6657 | AX57: -0.011390242 | AY57: 328.22347 | AZ57: 0.017026191 | BA57: 2223.3933 | BB57: -0.048332387 | BC57: 4497.2264 | BD57: -0.0040012463 | BE57: -2273.8331 | BF57: 0.043530811
A58: 1991 | B58: 3 | C58: 98305.664 | D58: 0.010575483 | E58: 96038.651 | F58: 0.010363959 | G58: 1907.4912 | H58: -0.02497325 | I58: 146.1722 | J58: -0.015949714 | K58: 19298.088 | L58: 0.0071861328 | M58: 3182.9792 | N58: 0.022926396 | O58: 16115.109 | P58: 0.0041343055 | Q58: 1799.3778 | R58: 0.020646263 | S58: 722.78312 | T58: -0.00085236491 | U58: 7294.8263 | V58: -0.0065287259 | W58: 14540.283 | X58: 0.0017943382 | Y58: 5116.2387 | Z58: 0.00012543999 | AA58: 4584.9493 | AB58: 0.032614944 | AC58: 2231.6504 | AD58: 0.019241566 | AE58: 4568.0865 | AF58: 0.011142741 | AG58: 7442.4378 | AH58: 0.0064653226 | AI58: 3236.2727 | AJ58: 0.01024663 | AK58: 3960.3219 | AL58: 0.0018245235 | AM58: 14151.588 | AN58: 0.018420243 | AO58: 6519.6245 | AP58: 0.019101862 | AQ58: 4184.2163 | AR58: 0.0046279994 | AS58: 4386.3782 | AT58: 0.041222577 | AU58: 400.34757 | AV58: 0.052937444 | AW58: 1526.1826 | AX58: 0.0016518597 | AY58: 334.16771 | AZ58: 0.018110343 | BA58: 2267.0129 | BB58: 0.019618466 | BC58: 4608.1617 | BD58: 0.024667485 | BE58: -2341.1488 | BF58: 0.029604503
A59: 1991 | B59: 4 | C59: 99078.617 | D59: 0.0078627551 | E59: 96905.992 | F59: 0.0090311635 | G59: 1865.6717 | H59: -0.021923812 | I59: 140.87055 | J59: -0.036269888 | K59: 19364.794 | L59: 0.0034565787 | M59: 3278.2634 | N59: 0.029935545 | O59: 16086.53 | P59: -0.0017734199 | Q59: 1964.8924 | R59: 0.091984382 | S59: 725.68558 | T59: 0.0040156722 | U59: 7125.61 | V59: -0.023196757 | W59: 14892.448 | X59: 0.024219953 | Y59: 5267.0629 | Z59: 0.029479504 | AA59: 4564.9963 | AB59: -0.0043518513 | AC59: 2238.7314 | AD59: 0.0031729852 | AE59: 4565.0013 | AF59: -0.00067538709 | AG59: 7446.6208 | AH59: 0.00056204666 | AI59: 3228.2247 | AJ59: -0.0024868154 | AK59: 3973.0107 | AL59: 0.0032039827 | AM59: 14423.484 | AN59: 0.01921308 | AO59: 6651.6574 | AP59: 0.020251622 | AQ59: 4248.858 | AR59: 0.015448932 | AS59: 4425.5194 | AT59: 0.0089233609 | AU59: 402.27332 | AV59: 0.0048101885 | AW59: 1518.96 | AX59: -0.0047324388 | AY59: 339.91807 | AZ59: 0.01720799 | BA59: 2172.6255 | BB59: -0.041635141 | BC59: 4527.2015 | BD59: -0.017568855 | BE59: -2354.576 | BF59: 0.0057353379
A60: 1992 | B60: 1 | C60: 99828.955 | D60: 0.0075731521 | E60: 97641.259 | F60: 0.0075874245 | G60: 1825.0402 | H60: -0.021778454 | I60: 131.30507 | J60: -0.067902677 | K60: 19504.207 | L60: 0.0071993371 | M60: 3359.1569 | N60: 0.024675721 | O60: 16145.05 | P60: 0.0036378363 | Q60: 2000.8819 | R60: 0.018316274 | S60: 721.19216 | T60: -0.0061919722 | U60: 7070.3914 | V60: -0.0077493163 | W60: 15077.862 | X60: 0.012450196 | Y60: 5241.2735 | Z60: -0.0048963608 | AA60: 4495.3652 | AB60: -0.015253265 | AC60: 2250.3046 | AD60: 0.0051695235 | AE60: 4597.2487 | AF60: 0.0070640532 | AG60: 7508.2283 | AH60: 0.008273215 | AI60: 3273.1138 | AJ60: 0.01390519 | AK60: 3989.3235 | AL60: 0.0041059239 | AM60: 14670.327 | AN60: 0.017113944 | AO60: 6773.389 | AP60: 0.018300938 | AQ60: 4270.3022 | AR60: 0.0050470392 | AS60: 4490.0438 | AT60: 0.014580056 | AU60: 394.79714 | AV60: -0.018584841 | AW60: 1516.394 | AX60: -0.0016893176 | AY60: 343.97931 | AZ60: 0.011947705 | BA60: 2187.696 | BB60: 0.0069365582 | BC60: 4552.0558 | BD60: 0.0054899924 | BE60: -2364.3598 | BF60: 0.0041552103
A61: 1992 | B61: 2 | C61: 100088.85 | D61: 0.0026034084 | E61: 97983.351 | F61: 0.0035035621 | G61: 1800.9172 | H61: -0.013217802 | I61: 126.23191 | J61: -0.038636381 | K61: 19367.487 | L61: -0.0070097858 | M61: 3359.9698 | N61: 0.00024198601 | O61: 16007.517 | P61: -0.0085185974 | Q61: 2031.8759 | R61: 0.01549017 | S61: 717.42284 | T61: -0.0052265106 | U61: 6933.5164 | V61: -0.019358904 | W61: 15255.767 | X61: 0.01179907 | Y61: 5260.6792 | Z61: 0.0037024852 | AA61: 4507.4693 | AB61: 0.0026925682 | AC61: 2251.4659 | AD61: 0.00051606397 | AE61: 4579.783 | AF61: -0.0037991588 | AG61: 7556.4694 | AH61: 0.0064250976 | AI61: 3284.5987 | AJ61: 0.0035088903 | AK61: 4020.96 | AL61: 0.00793029 | AM61: 14837.577 | AN61: 0.011400578 | AO61: 6865.1795 | AP61: 0.013551641 | AQ61: 4292.7653 | AR61: 0.0052603056 | AS61: 4598.9888 | AT61: 0.024263683 | AU61: 388.2966 | AV61: -0.016465522 | AW61: 1524.3765 | AX61: 0.0052641439 | AY61: 347.76199 | AZ61: 0.010996826 | BA61: 2105.4994 | BB61: -0.037572254 | BC61: 4478.3513 | BD61: -0.016191472 | BE61: -2372.852 | BF61: 0.0035917497
A62: 1992 | B62: 3 | C62: 99659.838 | D62: -0.0042863118 | E62: 97593.906 | F62: -0.0039746045 | G62: 1787.5073 | H62: -0.0074461296 | I62: 125.14152 | J62: -0.008638044 | K62: 19257.679 | L62: -0.0056697221 | M62: 3364.4755 | N62: 0.0013410054 | O62: 15893.203 | P62: -0.0071412702 | Q62: 2140.4242 | R62: 0.053422704 | S62: 714.74124 | T62: -0.0037378288 | U62: 6781.6923 | V62: -0.02189712 | W62: 15096.024 | X62: -0.01047093 | Y62: 5208.9659 | Z62: -0.0098301639 | AA62: 4479.6567 | AB62: -0.0061703178 | AC62: 2255.4731 | AD62: 0.0017798356 | AE62: 4541.857 | AF62: -0.0082811876 | AG62: 7700.8001 | AH62: 0.019100274 | AI62: 3382.0752 | AJ62: 0.029676833 | AK62: 4072.1506 | AL62: 0.012730926 | AM62: 14817.814 | AN62: -0.0013319253 | AO62: 6873.5883 | AP62: 0.0012248369 | AQ62: 4368.6022 | AR62: 0.017666216 | AS62: 4457.6241 | AT62: -0.030738216 | AU62: 343.93483 | AV62: -0.11424712 | AW62: 1500.3331 | AX62: -0.015772636 | AY62: 351.01236 | AZ62: 0.0093465324 | BA62: 2065.9324 | BB62: -0.018792195 | BC62: 4442.7549 | BD62: -0.0079485587 | BE62: -2376.8225 | BF62: 0.0016733097
A63: 1992 | B63: 4 | C63: 99705.188 | D63: 0.00045504463 | E63: 97548.519 | F63: -0.00046505617 | G63: 1721.7502 | H63: -0.036787078 | I63: 125.55149 | J63: 0.0032760614 | K63: 19088.863 | L63: -0.0087661593 | M63: 3412.5943 | N63: 0.014302032 | O63: 15676.269 | P63: -0.013649528 | Q63: 2140.9569 | R63: 0.00024885092 | S63: 716.34617 | T63: 0.0022454704 | U63: 6718.6271 | V63: -0.0092993378 | W63: 14926.601 | X63: -0.011223084 | Y63: 5230.7937 | Z63: 0.0041904307 | AA63: 4367.2609 | AB63: -0.025090278 | AC63: 2256.0726 | AD63: 0.00026579 | AE63: 4460.1878 | AF63: -0.017981456 | AG63: 8206.6619 | AH63: 0.065689517 | AI63: 3800.7513 | AJ63: 0.12379265 | AK63: 4145.7835 | AL63: 0.018082071 | AM63: 14817.087 | AN63: -4.9103667e-05 | AO63: 6858.7578 | AP63: -0.0021576052 | AQ63: 4477.0947 | AR63: 0.024834598 | AS63: 4499.2802 | AT63: 0.0093449233 | AU63: 329.76795 | AV63: -0.041190586 | AW63: 1484.9055 | AX63: -0.010282766 | AY63: 352.74803 | AZ63: 0.004944778 | BA63: 2156.6687 | BB63: 0.043920276 | BC63: 4523.7982 | BD63: 0.018241672 | BE63: -2367.1295 | BF63: -0.0040781523
A64: 1993 | B64: 1 | C64: 100044.12 | D64: 0.0033993876 | E64: 97808.899 | F64: 0.0026692375 | G64: 1719.1451 | H64: -0.0015130652 | I64: 128.38043 | J64: 0.022532105 | K64: 19212.082 | L64: 0.0064550185 | M64: 3494.5917 | N64: 0.024027876 | O64: 15717.49 | P64: 0.0026295523 | Q64: 2158.5593 | R64: 0.0082217471 | S64: 700.62502 | T64: -0.021946292 | U64: 6528.8053 | V64: -0.028253069 | W64: 14692.28 | X64: -0.01569819 | Y64: 5149.778 | Z64: -0.01548822 | AA64: 4247.162 | AB64: -0.027499836 | AC64: 2268.3241 | AD64: 0.00543045 | AE64: 4425.0902 | AF64: -0.0078690791 | AG64: 8759.2155 | AH64: 0.067329887 | AI64: 4231.4451 | AJ64: 0.11331806 | AK64: 4243.6159 | AL64: 0.023598046 | AM64: 14817.164 | AN64: 5.2068491e-06 | AO64: 6879.7714 | AP64: 0.003063763 | AQ64: 4586.3436 | AR64: 0.02440174 | AS64: 4522.4472 | AT64: 0.0051490383 | AU64: 329.77524 | AV64: 2.2095264e-05 | AW64: 1479.3214 | AX64: -0.0037605335 | AY64: 354.40815 | AZ64: 0.0047062488 | BA64: 2235.2251 | BB64: 0.036424889 | BC64: 4602.3397 | BD64: 0.017361853 | BE64: -2367.1146 | BF64: -6.293875e-06
... A197: 2026 | B197: 2 | C197: 225390.74 | D197: 0.014908146 | E197: 219235.12 | F197: 0.014237079 | G197: 1273.5744 | H197: -0.023203255 | I197: 187.4162 | J197: -0.051499159 | K197: 41989.663 | L197: 0.029989145 | M197: 16980.852 | N197: 0.10960527 | O197: 25008.811 | P197: -0.017859807 | Q197: 2772.6832 | R197: 0.033430722 | S197: 684.50572 | T197: -0.0057091751 | U197: 10242.029 | V197: 0.0036574686 | W197: 34230.11 | X197: 0.022494571 | Y197: 6862.7767 | Z197: 0.0059824771 | AA197: 8175.0022 | AB197: 0.019773859 | AC197: 4073.7504 | AD197: 0.014503646 | AE197: 10390.91 | AF197: 0.010488521 | AG197: 19687.003 | AH197: 0.0017748855 | AI197: 8663.4954 | AJ197: 0.015858847 | AK197: 7094.0992 | AL197: -0.019654587 | AM197: 39900.947 | AN197: 0.0096048832 | AO197: 14365.763 | AP197: 0.0048158404 | AQ197: 9240.4383 | AR197: 0.00089551741 | AS197: 16913.234 | AT197: 0.0086327329 | AU197: 1781.9429 | AV197: 0.039026282 | AW197: 2692.2839 | AX197: -0.0040151732 | AY197: 633.85972 | AZ197: 0.0033722769 | BA197: 6155.6197 | BB197: 0.039401498 | BC197: 11114.238 | BD197: 0.021991467 | BE197: -4958.6188 | BF197: 0.0011735793

Sheet real_q
A1: =INDIRECT("beschriftung!"&ADDRESS(beschriftung!$C$1*12+ROW(beschriftung!$A1)-1,COLUMN(beschriftung!A$1))) -> ESA 2010, Quarterly aggregates of Gross Domestic Product, production approach, seasonally, calendar and sport event adjusted data. Background information on sport event adjustment can be found in the publication “Konjunkturtendenzen” (“Economic Trends”) from autumn 2022 and in the technical note from 5 September 2022 on the website www.seco.admin.ch.
A2: =INDIRECT("beschriftung!"&ADDRESS(beschriftung!$C$1*12+ROW(beschriftung!$A3)-1,COLUMN(beschriftung!A$1))) -> In Mio. Swiss Francs, at prices of the preceding year, chained values ("annual overlap"), reference year 2020, percentage change to previous quarter
C4: =INDIRECT("beschriftung!"&ADDRESS(beschriftung!$C$1*12+ROW(beschriftung!$A5)-1,COLUMN(beschriftung!C$1))) -> Gross domestic product | D4: =IF(INDIRECT("beschriftung.!"&ADDRESS(#REF!*12+ROW($A5)-1,COLUMN(D$1)))="","",INDIRECT("beschriftung.!"&ADDRESS(#REF!*12+ROW($A5)-1,COLUMN(D$1)))) -> #REF! | E4: =IF(INDIRECT("beschriftung.!"&ADDRESS(#REF!*12+ROW($A5)-1,COLUMN(E$1)))="","",INDIRECT("beschriftung.!"&ADDRESS(#REF!*12+ROW($A5)-1,COLUMN(E$1)))) -> #REF! | F4: =IF(INDIRECT("beschriftung.!"&ADDRESS(#REF!*12+ROW($A5)-1,COLUMN(F$1)))="","",INDIRECT("beschriftung.!"&ADDRESS(#REF!*12+ROW($A5)-1,COLUMN(F$1)))) -> #REF! | G4: =IF(INDIRECT("beschriftung.!"&ADDRESS(#REF!*12+ROW($A5)-1,COLUMN(G$1)))="","",INDIRECT("beschriftung.!"&ADDRESS(#REF!*12+ROW($A5)-1,COLUMN(G$1)))) -> #REF! | H4: =IF(INDIRECT("beschriftung.!"&ADDRESS(#REF!*12+ROW($A5)-1,COLUMN(H$1)))="","",INDIRECT("beschriftung.!"&ADDRESS(#REF!*12+ROW($A5)-1,COLUMN(H$1)))) -> #REF! | I4: =IF(INDIRECT("beschriftung.!"&ADDRESS(#REF!*12+ROW($A5)-1,COLUMN(I$1)))="","",INDIRECT("beschriftung.!"&ADDRESS(#REF!*12+ROW($A5)-1,COLUMN(I$1)))) -> #REF! | J4: =IF(INDIRECT("beschriftung.!"&ADDRESS(#REF!*12+ROW($A5)-1,COLUMN(J$1)))="","",INDIRECT("beschriftung.!"&ADDRESS(#REF!*12+ROW($A5)-1,COLUMN(J$1)))) -> #REF! | K4: =IF(INDIRECT("beschriftung.!"&ADDRESS(#REF!*12+ROW($A5)-1,COLUMN(K$1)))="","",INDIRECT("beschriftung.!"&ADDRESS(#REF!*12+ROW($A5)-1,COLUMN(K$1)))) -> #REF! | L4: =IF(INDIRECT("beschriftung.!"&ADDRESS(#REF!*12+ROW($A5)-1,COLUMN(L$1)))="","",INDIRECT("beschriftung.!"&ADDRESS(#REF!*12+ROW($A5)-1,COLUMN(L$1)))) -> #REF! | Q4: =IF(INDIRECT("beschriftung.!"&ADDRESS(#REF!*12+ROW($A5)-1,COLUMN(Q$1)))="","",INDIRECT("beschriftung.!"&ADDRESS(#REF!*12+ROW($A5)-1,COLUMN(Q$1)))) -> #REF! | R4: =IF(INDIRECT("beschriftung.!"&ADDRESS(#REF!*12+ROW($A5)-1,COLUMN(R$1)))="","",INDIRECT("beschriftung.!"&ADDRESS(#REF!*12+ROW($A5)-1,COLUMN(R$1)))) -> #REF! | U4: =IF(INDIRECT("beschriftung.!"&ADDRESS(#REF!*12+ROW($A5)-1,COLUMN(U$1)))="","",INDIRECT("beschriftung.!"&ADDRESS(#REF!*12+ROW($A5)-1,COLUMN(U$1)))) -> #REF! | V4: =IF(INDIRECT("beschriftung.!"&ADDRESS(#REF!*12+ROW($A5)-1,COLUMN(V$1)))="","",INDIRECT("beschriftung.!"&ADDRESS(#REF!*12+ROW($A5)-1,COLUMN(V$1)))) -> #REF! | W4: =IF(INDIRECT("beschriftung.!"&ADDRESS(#REF!*12+ROW($A5)-1,COLUMN(W$1)))="","",INDIRECT("beschriftung.!"&ADDRESS(#REF!*12+ROW($A5)-1,COLUMN(W$1)))) -> #REF! | X4: =IF(INDIRECT("beschriftung.!"&ADDRESS(#REF!*12+ROW($A5)-1,COLUMN(X$1)))="","",INDIRECT("beschriftung.!"&ADDRESS(#REF!*12+ROW($A5)-1,COLUMN(X$1)))) -> #REF! | AA4: =IF(INDIRECT("beschriftung.!"&ADDRESS(#REF!*12+ROW($A5)-1,COLUMN(AA$1)))="","",INDIRECT("beschriftung.!"&ADDRESS(#REF!*12+ROW($A5)-1,COLUMN(AA$1)))) -> #REF! | AB4: =IF(INDIRECT("beschriftung.!"&ADDRESS(#REF!*12+ROW($A5)-1,COLUMN(AB$1)))="","",INDIRECT("beschriftung.!"&ADDRESS(#REF!*12+ROW($A5)-1,COLUMN(AB$1)))) -> #REF! | AG4: =IF(INDIRECT("beschriftung.!"&ADDRESS(#REF!*12+ROW($A5)-1,COLUMN(AG$1)))="","",INDIRECT("beschriftung.!"&ADDRESS(#REF!*12+ROW($A5)-1,COLUMN(AG$1)))) -> #REF! | AH4: =IF(INDIRECT("beschriftung.!"&ADDRESS(#REF!*12+ROW($A5)-1,COLUMN(AH$1)))="","",INDIRECT("beschriftung.!"&ADDRESS(#REF!*12+ROW($A5)-1,COLUMN(AH$1)))) -> #REF! | AI4: =IF(INDIRECT("beschriftung.!"&ADDRESS(#REF!*12+ROW($A5)-1,COLUMN(AI$1)))="","",INDIRECT("beschriftung.!"&ADDRESS(#REF!*12+ROW($A5)-1,COLUMN(AI$1)))) -> #REF! | AJ4: =IF(INDIRECT("beschriftung.!"&ADDRESS(#REF!*12+ROW($A5)-1,COLUMN(AJ$1)))="","",INDIRECT("beschriftung.!"&ADDRESS(#REF!*12+ROW($A5)-1,COLUMN(AJ$1)))) -> #REF! | AM4: =IF(INDIRECT("beschriftung.!"&ADDRESS(#REF!*12+ROW($A5)-1,COLUMN(AM$1)))="","",INDIRECT("beschriftung.!"&ADDRESS(#REF!*12+ROW($A5)-1,COLUMN(AM$1)))) -> #REF! | AN4: =IF(INDIRECT("beschriftung.!"&ADDRESS(#REF!*12+ROW($A5)-1,COLUMN(AN$1)))="","",INDIRECT("beschriftung.!"&ADDRESS(#REF!*12+ROW($A5)-1,COLUMN(AN$1)))) -> #REF! | AO4: =IF(INDIRECT("beschriftung.!"&ADDRESS(#REF!*12+ROW($A5)-1,COLUMN(AO$1)))="","",INDIRECT("beschriftung.!"&ADDRESS(#REF!*12+ROW($A5)-1,COLUMN(AO$1)))) -> #REF! | AP4: =IF(INDIRECT("beschriftung.!"&ADDRESS(#REF!*12+ROW($A5)-1,COLUMN(AP$1)))="","",INDIRECT("beschriftung.!"&ADDRESS(#REF!*12+ROW($A5)-1,COLUMN(AP$1)))) -> #REF! | AQ4: =IF(INDIRECT("beschriftung.!"&ADDRESS(#REF!*12+ROW($A5)-1,COLUMN(AQ$1)))="","",INDIRECT("beschriftung.!"&ADDRESS(#REF!*12+ROW($A5)-1,COLUMN(AQ$1)))) -> #REF! | AR4: =IF(INDIRECT("beschriftung.!"&ADDRESS(#REF!*12+ROW($A5)-1,COLUMN(AR$1)))="","",INDIRECT("beschriftung.!"&ADDRESS(#REF!*12+ROW($A5)-1,COLUMN(AR$1)))) -> #REF! | AS4: =IF(INDIRECT("beschriftung.!"&ADDRESS(#REF!*12+ROW($A5)-1,COLUMN(AS$1)))="","",INDIRECT("beschriftung.!"&ADDRESS(#REF!*12+ROW($A5)-1,COLUMN(AS$1)))) -> #REF! | AT4: =IF(INDIRECT("beschriftung.!"&ADDRESS(#REF!*12+ROW($A5)-1,COLUMN(AT$1)))="","",INDIRECT("beschriftung.!"&ADDRESS(#REF!*12+ROW($A5)-1,COLUMN(AT$1)))) -> #REF! | ... AV4: =IF(INDIRECT("beschriftung.!"&ADDRESS(#REF!*12+ROW($A5)-1,COLUMN(AV$1)))="","",INDIRECT("beschriftung.!"&ADDRESS(#REF!*12+ROW($A5)-1,COLUMN(AV$1)))) -> #REF! | AY4: =IF(INDIRECT("beschriftung.!"&ADDRESS(#REF!*12+ROW($A5)-1,COLUMN(AY$1)))="","",INDIRECT("beschriftung.!"&ADDRESS(#REF!*12+ROW($A5)-1,COLUMN(AY$1)))) -> #REF! | AZ4: =IF(INDIRECT("beschriftung.!"&ADDRESS(#REF!*12+ROW($A5)-1,COLUMN(AZ$1)))="","",INDIRECT("beschriftung.!"&ADDRESS(#REF!*12+ROW($A5)-1,COLUMN(AZ$1)))) -> #REF! | BA4: =IF(INDIRECT("beschriftung.!"&ADDRESS(#REF!*12+ROW($A5)-1,COLUMN(BA$1)))="","",INDIRECT("beschriftung.!"&ADDRESS(#REF!*12+ROW($A5)-1,COLUMN(BA$1)))) -> #REF! | BB4: =IF(INDIRECT("beschriftung.!"&ADDRESS(#REF!*12+ROW($A5)-1,COLUMN(BB$1)))="","",INDIRECT("beschriftung.!"&ADDRESS(#REF!*12+ROW($A5)-1,COLUMN(BB$1)))) -> #REF! | BC4: =IF(INDIRECT("beschriftung.!"&ADDRESS(#REF!*12+ROW($A5)-1,COLUMN(BC$1)))="","",INDIRECT("beschriftung.!"&ADDRESS(#REF!*12+ROW($A5)-1,COLUMN(BC$1)))) -> #REF! | BD4: =IF(INDIRECT("beschriftung.!"&ADDRESS(#REF!*12+ROW($A5)-1,COLUMN(BD$1)))="","",INDIRECT("beschriftung.!"&ADDRESS(#REF!*12+ROW($A5)-1,COLUMN(BD$1)))) -> #REF! | BE4: =IF(INDIRECT("beschriftung.!"&ADDRESS(#REF!*12+ROW($A5)-1,COLUMN(BE$1)))="","",INDIRECT("beschriftung.!"&ADDRESS(#REF!*12+ROW($A5)-1,COLUMN(BE$1)))) -> #REF! | BF4: =IF(INDIRECT("beschriftung.!"&ADDRESS(#REF!*12+ROW($A5)-1,COLUMN(BF$1)))="","",INDIRECT("beschriftung.!"&ADDRESS(#REF!*12+ROW($A5)-1,COLUMN(BF$1)))) -> #REF!
E5: =INDIRECT("beschriftung!"&ADDRESS(beschriftung!$C$1*12+ROW(beschriftung!$A6)-1,COLUMN(beschriftung!D$1))) -> Gross value added before adjustments | F5: =IF(INDIRECT("beschriftung.!"&ADDRESS(#REF!*12+ROW($A6)-1,COLUMN(F$1)))="","",INDIRECT("beschriftung.!"&ADDRESS(#REF!*12+ROW($A6)-1,COLUMN(F$1)))) -> #REF! | G5: =IF(INDIRECT("beschriftung.!"&ADDRESS(#REF!*12+ROW($A6)-1,COLUMN(G$1)))="","",INDIRECT("beschriftung.!"&ADDRESS(#REF!*12+ROW($A6)-1,COLUMN(G$1)))) -> #REF! | H5: =IF(INDIRECT("beschriftung.!"&ADDRESS(#REF!*12+ROW($A6)-1,COLUMN(H$1)))="","",INDIRECT("beschriftung.!"&ADDRESS(#REF!*12+ROW($A6)-1,COLUMN(H$1)))) -> #REF! | I5: =IF(INDIRECT("beschriftung.!"&ADDRESS(#REF!*12+ROW($A6)-1,COLUMN(I$1)))="","",INDIRECT("beschriftung.!"&ADDRESS(#REF!*12+ROW($A6)-1,COLUMN(I$1)))) -> #REF! | J5: =IF(INDIRECT("beschriftung.!"&ADDRESS(#REF!*12+ROW($A6)-1,COLUMN(J$1)))="","",INDIRECT("beschriftung.!"&ADDRESS(#REF!*12+ROW($A6)-1,COLUMN(J$1)))) -> #REF! | K5: =IF(INDIRECT("beschriftung.!"&ADDRESS(#REF!*12+ROW($A6)-1,COLUMN(K$1)))="","",INDIRECT("beschriftung.!"&ADDRESS(#REF!*12+ROW($A6)-1,COLUMN(K$1)))) -> #REF! | L5: =IF(INDIRECT("beschriftung.!"&ADDRESS(#REF!*12+ROW($A6)-1,COLUMN(L$1)))="","",INDIRECT("beschriftung.!"&ADDRESS(#REF!*12+ROW($A6)-1,COLUMN(L$1)))) -> #REF! | Q5: =IF(INDIRECT("beschriftung.!"&ADDRESS(#REF!*12+ROW($A6)-1,COLUMN(Q$1)))="","",INDIRECT("beschriftung.!"&ADDRESS(#REF!*12+ROW($A6)-1,COLUMN(Q$1)))) -> #REF! | R5: =IF(INDIRECT("beschriftung.!"&ADDRESS(#REF!*12+ROW($A6)-1,COLUMN(R$1)))="","",INDIRECT("beschriftung.!"&ADDRESS(#REF!*12+ROW($A6)-1,COLUMN(R$1)))) -> #REF! | U5: =IF(INDIRECT("beschriftung.!"&ADDRESS(#REF!*12+ROW($A6)-1,COLUMN(U$1)))="","",INDIRECT("beschriftung.!"&ADDRESS(#REF!*12+ROW($A6)-1,COLUMN(U$1)))) -> #REF! | V5: =IF(INDIRECT("beschriftung.!"&ADDRESS(#REF!*12+ROW($A6)-1,COLUMN(V$1)))="","",INDIRECT("beschriftung.!"&ADDRESS(#REF!*12+ROW($A6)-1,COLUMN(V$1)))) -> #REF! | W5: =IF(INDIRECT("beschriftung.!"&ADDRESS(#REF!*12+ROW($A6)-1,COLUMN(W$1)))="","",INDIRECT("beschriftung.!"&ADDRESS(#REF!*12+ROW($A6)-1,COLUMN(W$1)))) -> #REF! | X5: =IF(INDIRECT("beschriftung.!"&ADDRESS(#REF!*12+ROW($A6)-1,COLUMN(X$1)))="","",INDIRECT("beschriftung.!"&ADDRESS(#REF!*12+ROW($A6)-1,COLUMN(X$1)))) -> #REF! | AA5: =IF(INDIRECT("beschriftung.!"&ADDRESS(#REF!*12+ROW($A6)-1,COLUMN(AA$1)))="","",INDIRECT("beschriftung.!"&ADDRESS(#REF!*12+ROW($A6)-1,COLUMN(AA$1)))) -> #REF! | AB5: =IF(INDIRECT("beschriftung.!"&ADDRESS(#REF!*12+ROW($A6)-1,COLUMN(AB$1)))="","",INDIRECT("beschriftung.!"&ADDRESS(#REF!*12+ROW($A6)-1,COLUMN(AB$1)))) -> #REF! | AG5: =IF(INDIRECT("beschriftung.!"&ADDRESS(#REF!*12+ROW($A6)-1,COLUMN(AG$1)))="","",INDIRECT("beschriftung.!"&ADDRESS(#REF!*12+ROW($A6)-1,COLUMN(AG$1)))) -> #REF! | AH5: =IF(INDIRECT("beschriftung.!"&ADDRESS(#REF!*12+ROW($A6)-1,COLUMN(AH$1)))="","",INDIRECT("beschriftung.!"&ADDRESS(#REF!*12+ROW($A6)-1,COLUMN(AH$1)))) -> #REF! | AI5: =IF(INDIRECT("beschriftung.!"&ADDRESS(#REF!*12+ROW($A6)-1,COLUMN(AI$1)))="","",INDIRECT("beschriftung.!"&ADDRESS(#REF!*12+ROW($A6)-1,COLUMN(AI$1)))) -> #REF! | AJ5: =IF(INDIRECT("beschriftung.!"&ADDRESS(#REF!*12+ROW($A6)-1,COLUMN(AJ$1)))="","",INDIRECT("beschriftung.!"&ADDRESS(#REF!*12+ROW($A6)-1,COLUMN(AJ$1)))) -> #REF! | AM5: =IF(INDIRECT("beschriftung.!"&ADDRESS(#REF!*12+ROW($A6)-1,COLUMN(AM$1)))="","",INDIRECT("beschriftung.!"&ADDRESS(#REF!*12+ROW($A6)-1,COLUMN(AM$1)))) -> #REF! | AN5: =IF(INDIRECT("beschriftung.!"&ADDRESS(#REF!*12+ROW($A6)-1,COLUMN(AN$1)))="","",INDIRECT("beschriftung.!"&ADDRESS(#REF!*12+ROW($A6)-1,COLUMN(AN$1)))) -> #REF! | AO5: =IF(INDIRECT("beschriftung.!"&ADDRESS(#REF!*12+ROW($A6)-1,COLUMN(AO$1)))="","",INDIRECT("beschriftung.!"&ADDRESS(#REF!*12+ROW($A6)-1,COLUMN(AO$1)))) -> #REF! | AP5: =IF(INDIRECT("beschriftung.!"&ADDRESS(#REF!*12+ROW($A6)-1,COLUMN(AP$1)))="","",INDIRECT("beschriftung.!"&ADDRESS(#REF!*12+ROW($A6)-1,COLUMN(AP$1)))) -> #REF! | AQ5: =IF(INDIRECT("beschriftung.!"&ADDRESS(#REF!*12+ROW($A6)-1,COLUMN(AQ$1)))="","",INDIRECT("beschriftung.!"&ADDRESS(#REF!*12+ROW($A6)-1,COLUMN(AQ$1)))) -> #REF! | AR5: =IF(INDIRECT("beschriftung.!"&ADDRESS(#REF!*12+ROW($A6)-1,COLUMN(AR$1)))="","",INDIRECT("beschriftung.!"&ADDRESS(#REF!*12+ROW($A6)-1,COLUMN(AR$1)))) -> #REF! | AS5: =IF(INDIRECT("beschriftung.!"&ADDRESS(#REF!*12+ROW($A6)-1,COLUMN(AS$1)))="","",INDIRECT("beschriftung.!"&ADDRESS(#REF!*12+ROW($A6)-1,COLUMN(AS$1)))) -> #REF! | AT5: =IF(INDIRECT("beschriftung.!"&ADDRESS(#REF!*12+ROW($A6)-1,COLUMN(AT$1)))="","",INDIRECT("beschriftung.!"&ADDRESS(#REF!*12+ROW($A6)-1,COLUMN(AT$1)))) -> #REF! | ... AV5: =IF(INDIRECT("beschriftung.!"&ADDRESS(#REF!*12+ROW($A6)-1,COLUMN(AV$1)))="","",INDIRECT("beschriftung.!"&ADDRESS(#REF!*12+ROW($A6)-1,COLUMN(AV$1)))) -> #REF! | AY5: =IF(INDIRECT("beschriftung.!"&ADDRESS(#REF!*12+ROW($A6)-1,COLUMN(AY$1)))="","",INDIRECT("beschriftung.!"&ADDRESS(#REF!*12+ROW($A6)-1,COLUMN(AY$1)))) -> #REF! | AZ5: =IF(INDIRECT("beschriftung.!"&ADDRESS(#REF!*12+ROW($A6)-1,COLUMN(AZ$1)))="","",INDIRECT("beschriftung.!"&ADDRESS(#REF!*12+ROW($A6)-1,COLUMN(AZ$1)))) -> #REF! | BA5: =INDIRECT("beschriftung!"&ADDRESS(beschriftung!$C$1*12+ROW(beschriftung!$A6)-1,COLUMN(beschriftung!AS$1))) -> Adjustments | BB5: =IF(INDIRECT("beschriftung.!"&ADDRESS(#REF!*12+ROW($A6)-1,COLUMN(BB$1)))="","",INDIRECT("beschriftung.!"&ADDRESS(#REF!*12+ROW($A6)-1,COLUMN(BB$1)))) -> #REF! | BC5: =IF(INDIRECT("beschriftung.!"&ADDRESS(#REF!*12+ROW($A6)-1,COLUMN(BC$1)))="","",INDIRECT("beschriftung.!"&ADDRESS(#REF!*12+ROW($A6)-1,COLUMN(BC$1)))) -> #REF! | BD5: =IF(INDIRECT("beschriftung.!"&ADDRESS(#REF!*12+ROW($A6)-1,COLUMN(BD$1)))="","",INDIRECT("beschriftung.!"&ADDRESS(#REF!*12+ROW($A6)-1,COLUMN(BD$1)))) -> #REF! | BE5: =IF(INDIRECT("beschriftung.!"&ADDRESS(#REF!*12+ROW($A6)-1,COLUMN(BE$1)))="","",INDIRECT("beschriftung.!"&ADDRESS(#REF!*12+ROW($A6)-1,COLUMN(BE$1)))) -> #REF! | BF5: =IF(INDIRECT("beschriftung.!"&ADDRESS(#REF!*12+ROW($A6)-1,COLUMN(BF$1)))="","",INDIRECT("beschriftung.!"&ADDRESS(#REF!*12+ROW($A6)-1,COLUMN(BF$1)))) -> #REF!
G6: =INDIRECT("beschriftung!"&ADDRESS(beschriftung!$C$1*12+ROW(beschriftung!$A7)-1,COLUMN(beschriftung!E$1))) -> Agriculture, forestry and fishing | I6: =INDIRECT("beschriftung!"&ADDRESS(beschriftung!$C$1*12+ROW(beschriftung!$A7)-1,COLUMN(beschriftung!G$1))) -> Mining and quarrying | K6: =INDIRECT("beschriftung!"&ADDRESS(beschriftung!$C$1*12+ROW(beschriftung!$A7)-1,COLUMN(beschriftung!I$1))) -> Manufacturing | Q6: =INDIRECT("beschriftung!"&ADDRESS(beschriftung!$C$1*12+ROW(beschriftung!$A7)-1,COLUMN(beschriftung!M$1))) -> Electricity, gas, steam and air conditioning supply | S6: =INDIRECT("beschriftung!"&ADDRESS(beschriftung!$C$1*12+ROW(beschriftung!$A7)-1,COLUMN(beschriftung!O$1))) -> Water supply, sewerage, waste management and remediation activities | U6: =INDIRECT("beschriftung!"&ADDRESS(beschriftung!$C$1*12+ROW(beschriftung!$A7)-1,COLUMN(beschriftung!Q$1))) -> Construction | W6: =INDIRECT("beschriftung!"&ADDRESS(beschriftung!$C$1*12+ROW(beschriftung!$A7)-1,COLUMN(beschriftung!S$1))) -> Trade, repair of motor vehicles and motorcycles | AA6: =INDIRECT("beschriftung!"&ADDRESS(beschriftung!$C$1*12+ROW(beschriftung!$A7)-1,COLUMN(beschriftung!W$1))) -> Transportation and storage | AC6: =INDIRECT("beschriftung!"&ADDRESS(beschriftung!$C$1*12+ROW(beschriftung!$A7)-1,COLUMN(beschriftung!Y$1))) -> Accommodation and food service activities | AE6: =INDIRECT("beschriftung!"&ADDRESS(beschriftung!$C$1*12+ROW(beschriftung!$A7)-1,COLUMN(beschriftung!X$1))) -> Information and communication | AG6: =INDIRECT("beschriftung!"&ADDRESS(beschriftung!$C$1*12+ROW(beschriftung!$A7)-1,COLUMN(beschriftung!AA$1))) -> Financial and insurance activities | AM6: =INDIRECT("beschriftung!"&ADDRESS(beschriftung!$C$1*12+ROW(beschriftung!$A7)-1,COLUMN(beschriftung!AE$1))) -> Real estate, professional, scientific, technical activities and administrative services | AO6: =INDIRECT("beschriftung!"&ADDRESS(beschriftung!$C$1*12+ROW(beschriftung!$A7)-1,COLUMN(beschriftung!AG$1))) -> Public administration | AQ6: =INDIRECT("beschriftung!"&ADDRESS(beschriftung!$C$1*12+ROW(beschriftung!$A7)-1,COLUMN(beschriftung!AI$1))) -> Education | AS6: =INDIRECT("beschriftung!"&ADDRESS(beschriftung!$C$1*12+ROW(beschriftung!$A7)-1,COLUMN(beschriftung!AK$1))) -> Human health and social work activities | AU6: =INDIRECT("beschriftung!"&ADDRESS(beschriftung!$C$1*12+ROW(beschriftung!$A7)-1,COLUMN(beschriftung!AM$1))) -> Arts, entertainment and recreation | AW6: =INDIRECT("beschriftung!"&ADDRESS(beschriftung!$C$1*12+ROW(beschriftung!$A7)-1,COLUMN(beschriftung!AO$1))) -> Other service activities | AY6: =INDIRECT("beschriftung!"&ADDRESS(beschriftung!$C$1*12+ROW(beschriftung!$A7)-1,COLUMN(beschriftung!AQ$1))) -> Activities of housholds as employers and producers for own use | BC6: =INDIRECT("beschriftung!"&ADDRESS(beschriftung!$C$1*12+ROW(beschriftung!$A7)-1,COLUMN(beschriftung!AU$1))) -> Taxes on products | BE6: =INDIRECT("beschriftung!"&ADDRESS(beschriftung!$C$1*12+ROW(beschriftung!$A7)-1,COLUMN(beschriftung!AW$1))) -> Subsidies on products
M8: =INDIRECT("beschriftung!"&ADDRESS(beschriftung!$C$1*12+ROW(beschriftung!$A7),COLUMN(beschriftung!J$1))) -> thereof chemicals and pharmaceuticals | O8: =INDIRECT("beschriftung!"&ADDRESS(beschriftung!$C$1*12+ROW(beschriftung!$A7),COLUMN(beschriftung!K$1))) -> thereof other manufacturing | Y8: =INDIRECT("beschriftung!"&ADDRESS(beschriftung!$C$1*12+ROW(beschriftung!$A7),COLUMN(beschriftung!U$1))) -> thereof retail trade | AI8: =INDIRECT("beschriftung!"&ADDRESS(beschriftung!$C$1*12+ROW(beschriftung!$A7),COLUMN(beschriftung!AB$1))) -> thereof financial activities | AK8: {=INDIRECT("beschriftung!"&ADDRESS(beschriftung!$C$1*12+ROW(beschriftung!$A7),COLUMN(beschriftung!AC$1)))} -> thereof insurance activities
C11: B1GQ | E11: B1G | G11: NOGA 01-03 | I11: NOGA 05-09 | K11: NOGA 10-33 | M11: NOGA 19-21 | O11: NOGA 10-18; 22-33 | Q11: NOGA 35 | S11: NOGA 36-39 | U11: NOGA 41-43 | W11: NOGA 45-47 | Y11: NOGA 47 | AA11: NOGA 49-53 | AC11: NOGA 55-56 | AE11: NOGA 58-63 | AG11: NOGA 64-66 | AI11: NOGA 64 | AK11: NOGA 65 | AM11: NOGA 68-75; 77-82 | AO11: NOGA 84 | AQ11: NOGA 85 | AS11: NOGA 86-88 | AU11: NOGA 90-93 | AW11: NOGA 94-96 | AY11: NOGA 97-98 | BC11: D21 | BE11: D31
A12: 1980 | B12: 1 | C12: 91185.622
A13: 1980 | B13: 2 | C13: 91648.332 | D13: 0.0050743826
A14: 1980 | B14: 3 | C14: 92095.817 | D14: 0.0048826237
A15: 1980 | B15: 4 | C15: 92633.411 | D15: 0.005837342
A16: 1981 | B16: 1 | C16: 92652.065 | D16: 0.00020137038
A17: 1981 | B17: 2 | C17: 93533.535 | D17: 0.009513762
A18: 1981 | B18: 3 | C18: 93814.683 | D18: 0.0030058534
A19: 1981 | B19: 4 | C19: 93668.852 | D19: -0.0015544579
A20: 1982 | B20: 1 | C20: 92862.801 | D20: -0.0086053238
A21: 1982 | B21: 2 | C21: 92384.199 | D21: -0.0051538672
A22: 1982 | B22: 3 | C22: 91723.691 | D22: -0.0071495693
A23: 1982 | B23: 4 | C23: 91723.293 | D23: -4.3453781e-06
A24: 1983 | B24: 1 | C24: 92197.424 | D24: 0.0051691476
... A51: 1989 | B51: 4 | C51: 112183.34 | D51: 0.0092922007
A52: 1990 | B52: 1 | C52: 114393.67 | D52: 0.019702806 | E52: 111956.54 | G52: 1283.4175 | I52: 198.76749 | K52: 17508.36 | M52: 1340.656 | O52: 19269.644 | Q52: 3280.1474 | S52: 316.41667 | U52: 9199.5162 | W52: 16825.843 | Y52: 4811.5658 | AA52: 6011.9843 | AC52: 3608.5801 | AE52: 4240.9433 | AG52: 6484.8802 | AI52: 3877.3057 | AK52: 2070.8627 | AM52: 22298.375 | AO52: 8573.102 | AQ52: 6717.7655 | AS52: 5605.7653 | AU52: 728.91573 | AW52: 3266.5511 | AY52: 414.7823 | BA52: 2622.8346 | BC52: 5410.5934 | BE52: -2938.6478
A53: 1990 | B53: 2 | C53: 114872.4 | D53: 0.0041849567 | E53: 112343.04 | F53: 0.0034522804 | G53: 1265.1256 | H53: -0.014252474 | I53: 197.58634 | J53: -0.0059423855 | K53: 17540.472 | L53: 0.0018340988 | M53: 1352.8 | N53: 0.0090582209 | O53: 19278.324 | P53: 0.00045045291 | Q53: 3408.3341 | R53: 0.039079573 | S53: 322.47115 | T53: 0.019134495 | U53: 9195.2557 | V53: -0.00046311594 | W53: 16960.437 | X53: 0.0079992364 | Y53: 4865.512 | Z53: 0.011211789 | AA53: 5877.0532 | AB53: -0.022443689 | AC53: 3714.5204 | AD53: 0.029357904 | AE53: 4252.763 | AF53: 0.0027870421 | AG53: 6404.8865 | AH53: -0.012335413 | AI53: 3707.4433 | AJ53: -0.043809371 | AK53: 2102.0849 | AL53: 0.015076887 | AM53: 22388.193 | AN53: 0.0040279971 | AO53: 8702.581 | AP53: 0.015102938 | AQ53: 6863.923 | AR53: 0.021756863 | AS53: 5621.8011 | AT53: 0.0028605991 | AU53: 710.42893 | AV53: -0.025362063 | AW53: 3241.9601 | AX53: -0.0075281273 | AY53: 422.37793 | AZ53: 0.018312326 | BA53: 2708.2297 | BB53: 0.03255833 | BC53: 5437.8353 | BD53: 0.0050349216 | BE53: -2860.4712 | BF53: -0.026602917
A54: 1990 | B54: 3 | C54: 114808.09 | D54: -0.00055986343 | E54: 112289.02 | F54: -0.00048091767 | G54: 1251.2669 | H54: -0.010954377 | I54: 197.76675 | J54: 0.00091308826 | K54: 17561.683 | L54: 0.0012092599 | M54: 1356.4234 | N54: 0.0026784586 | O54: 19296.165 | P54: 0.00092544115 | Q54: 3350.6139 | R54: -0.016935031 | S54: 331.04014 | T54: 0.026572895 | U54: 9247.6105 | V54: 0.0056936754 | W54: 16638.18 | X54: -0.019000509 | Y54: 4814.8438 | Z54: -0.01041376 | AA54: 5880.3423 | AB54: 0.00055965716 | AC54: 3760.2241 | AD54: 0.012304061 | AE54: 4298.1488 | AF54: 0.010672079 | AG54: 6382.1245 | AH54: -0.003553852 | AI54: 3626.1514 | AJ54: -0.021926698 | AK54: 2127.4265 | AL54: 0.012055446 | AM54: 22504.19 | AN54: 0.0051811787 | AO54: 8794.2211 | AP54: 0.010530223 | AQ54: 6930.3627 | AR54: 0.0096795549 | AS54: 5632.3271 | AT54: 0.0018723444 | AU54: 743.03441 | AV54: 0.045895488 | AW54: 3209.4897 | AX54: -0.01001569 | AY54: 426.47963 | AZ54: 0.0097109599 | BA54: 2698.6672 | BB54: -0.0035309082 | BC54: 5432.2562 | BD54: -0.0010259665 | BE54: -2866.2735 | BF54: 0.0020284395
A55: 1990 | B55: 4 | C55: 114144.44 | D55: -0.0057804693 | E55: 111677.72 | F55: -0.0054439533 | G55: 1248.3392 | H55: -0.0023397823 | I55: 201.09103 | J55: 0.01680908 | K55: 17687.447 | L55: 0.0071612471 | M55: 1374.3365 | N55: 0.013206147 | O55: 19411.777 | P55: 0.0059914525 | Q55: 3456.8367 | R55: 0.031702505 | S55: 341.43032 | T55: 0.031386474 | U55: 9181.548 | V55: -0.0071437386 | W55: 15916.532 | X55: -0.043373009 | Y55: 4719.9638 | Z55: -0.019705724 | AA55: 6020.7318 | AB55: 0.023874379 | AC55: 3778.0443 | AD55: 0.0047391149 | AE55: 4323.8954 | AF55: 0.0059901559 | AG55: 6259.3132 | AH55: -0.019243021 | AI55: 3424.3608 | AJ55: -0.055648694 | AK55: 2146.8686 | AL55: 0.0091387738 | AM55: 22520.645 | AN55: 0.00073118751 | AO55: 8865.1225 | AP55: 0.0080622735 | AQ55: 6917.1463 | AR55: -0.0019070314 | AS55: 5642.5074 | AT55: 0.0018074703 | AU55: 769.34081 | AV55: 0.035404019 | AW55: 3120.0496 | AX55: -0.027867387 | AY55: 427.11453 | AZ55: 0.0014886986 | BA55: 2648.7859 | BB55: -0.018483683 | BC55: 5395.9026 | BD55: -0.0066921692 | BE55: -2888.0745 | BF55: 0.0076060677
A56: 1991 | B56: 1 | C56: 114396.85 | D56: 0.0022113238 | E56: 112051.08 | F56: 0.0033431999 | G56: 1245.9315 | H56: -0.0019287339 | I56: 198.0706 | J56: -0.015020184 | K56: 17728.251 | L56: 0.0023069728 | M56: 1392.8352 | N56: 0.013460055 | O56: 19415.405 | P56: 0.00018689872 | Q56: 3521.9195 | R56: 0.018827273 | S56: 352.55696 | T56: 0.032588317 | U56: 9076.2764 | V56: -0.011465565 | W56: 15753.199 | X56: -0.010261813 | Y56: 4642.584 | Z56: -0.016394138 | AA56: 6344.3062 | AB56: 0.053743359 | AC56: 3781.8401 | AD56: 0.0010047014 | AE56: 4341.0445 | AF56: 0.0039661259 | AG56: 6533.8868 | AH56: 0.04386641 | AI56: 3752.5266 | AJ56: 0.095832716 | AK56: 2160.1293 | AL56: 0.0061767769 | AM56: 22559.468 | AN56: 0.0017238939 | AO56: 8851.8772 | AP56: -0.0014940996 | AQ56: 6824.2615 | AR56: -0.0134282 | AS56: 5666.3589 | AT56: 0.004227112 | AU56: 813.91873 | AV56: 0.057943006 | AW56: 2975.2567 | AX56: -0.046407236 | AY56: 424.42467 | AZ56: -0.0062977496 | BA56: 2543.928 | BB56: -0.039587175 | BC56: 5389.9976 | BD56: -0.0010943622 | BE56: -3021.4004 | BF56: 0.046164274
A57: 1991 | B57: 2 | C57: 113208.38 | D57: -0.010389001 | E57: 110987.75 | F57: -0.0094897106 | G57: 1250.4509 | H57: 0.0036272779 | I57: 200.18424 | J57: 0.010671141 | K57: 17611.973 | L57: -0.006558947 | M57: 1409.4635 | N57: 0.011938486 | O57: 19218.212 | P57: -0.010156503 | Q57: 3381.1829 | R57: -0.039960213 | S57: 362.80708 | T57: 0.029073645 | U57: 8988.616 | V57: -0.0096581908 | W57: 15002.519 | X57: -0.047652555 | Y57: 4560.9363 | Z57: -0.0175867 | AA57: 6551.8957 | AB57: 0.032720605 | AC57: 3755.3692 | AD57: -0.006999476 | AE57: 4358.6433 | AF57: 0.0040540513 | AG57: 6686.8442 | AH57: 0.023409864 | AI57: 3892.1229 | AJ57: 0.037200637 | AK57: 2185.1495 | AL57: 0.011582729 | AM57: 22350.826 | AN57: -0.0092485245 | AO57: 8845.1229 | AP57: -0.00076302796 | AQ57: 6753.4561 | AR57: -0.010375541 | AS57: 5664.5298 | AT57: -0.00032280164 | AU57: 784.53595 | AV57: -0.036100387 | AW57: 2840.7781 | AX57: -0.045198996 | AY57: 422.59244 | AZ57: -0.0043169775 | BA57: 2428.9566 | BB57: -0.045194418 | BC57: 5329.0463 | BD57: -0.011308221 | BE57: -3102.2611 | BF57: 0.026762668
A58: 1991 | B58: 3 | C58: 113117.48 | D58: -0.00080292595 | E58: 110971.23 | F58: -0.00014886123 | G58: 1256.6457 | H58: 0.0049540675 | I58: 196.72489 | J58: -0.017280849 | K58: 17662.152 | L58: 0.002849162 | M58: 1444.4971 | N58: 0.024855963 | O58: 19188.876 | P58: -0.0015264687 | Q58: 3435.3569 | R58: 0.016022222 | S58: 375.0574 | T58: 0.033765391 | U58: 8915.9069 | V58: -0.0080890183 | W58: 14839.22 | X58: -0.010884765 | Y58: 4523.0645 | Z58: -0.0083035247 | AA58: 6689.539 | AB58: 0.021008169 | AC58: 3754.8501 | AD58: -0.00013821455 | AE58: 4382.9401 | AF58: 0.0055743857 | AG58: 6687.1956 | AH58: 5.2552892e-05 | AI58: 3801.6194 | AJ58: -0.023253002 | AK58: 2221.8959 | AL58: 0.016816434 | AM58: 22345.243 | AN58: -0.00024981119 | AO58: 8865.2727 | AP58: 0.0022780623 | AQ58: 6704.6644 | AR58: -0.0072246987 | AS58: 5681.9826 | AT58: 0.0030810709 | AU58: 793.2109 | AV58: 0.011057429 | AW58: 2787.4552 | AX58: -0.018770533 | AY58: 421.42571 | AZ58: -0.0027608678 | BA58: 2363.2194 | BB58: -0.027063971 | BC58: 5292.5234 | BD58: -0.0068535475 | BE58: -3146.5038 | BF58: 0.014261424
